Workbook

Sheet 功能测试用例
A1: AI Agent 多角色圆桌对谈与剧本生成系统功能测试用例表
A2: 生成日期：2026-07-09 测试范围：登录注册、内容生成、多 Agent 圆桌、Tool Calling、RAG、Memory、自定义 Agent、文档与自动化测试
A4: 用例编号 | B4: 一级模块 | C4: 二级功能/测试点 | D4: 用例标题 | E4: 前置条件 | F4: 操作步骤 | G4: 测试数据 | H4: 预期结果 | I4: 实际结果 | J4: 优先级 | K4: 严重程度 | L4: 测试类型 | M4: 执行状态 | N4: 回归结果 | O4: 备注
A5: TC-001 | B5: 登录注册 | C5: 页面访问 | D5: 未登录访问系统自动跳转登录页 | E5: 浏览器未登录，localStorage 无 token | F5: 打开 http://localhost:5174 或 /app/tree-hole?view=content | G5: token 为空 | H5: 跳转到登录/注册页，不直接进入系统页面 | I5: 与预期一致 | J5: P0 | K5: 高 | L5: 功能/鉴权 | M5: 通过 | N5: 通过 | O5: 验证路由守卫
A6: TC-002 | B6: 登录注册 | C6: 注册 | D6: 新用户注册后自动登录 | E6: 打开登录页 | F6: 切换到注册，输入新用户名和密码，点击注册 | G6: username=test01；password=123456 | H6: 注册成功，保存 token 和当前用户，自动进入内容选择页 | I6: 登录后默认进入多 Agent 协助页， 未进入生成方式选择页 | J6: P0 | K6: 高 | L6: 功能 | M6: 失败 | N6: 通过 | O6: BUG-001
A7: TC-003 | B7: 登录注册 | C7: 登录 | D7: 已有账号正确登录 | E7: 已有账号存在 | F7: 输入正确用户名和密码，点击登录 | G7: demo / 123456 | H7: 登录成功，进入内容页，默认展示两个生成入口 | I7: 游客登录失败，提示未获取到 token | J7: P0 | K7: 高 | L7: 功能 | M7: 通过 | N7: 通过
A8: TC-004 | B8: 登录注册 | C8: 登录异常 | D8: 错误密码登录失败 | E8: 已有账号存在 | F8: 输入正确用户名和错误密码，点击登录 | G8: demo / wrongpwd | H8: 提示登录失败，不保存 token，不进入系统 | I8: 与预期一致 | J8: P1 | K8: 中 | L8: 异常 | M8: 失败 | N8: 通过 | O8: BUG-002
A9: TC-005 | B9: 登录注册 | C9: 游客登录 | D9: 游客登录进入系统 | E9: 打开登录页 | F9: 点击游客登录按钮 | G9: 游客账号自动生成 | H9: 游客登录成功，进入内容选择页，并保存游客用户名 | I9: 与预期一致 | J9: P0 | K9: 高 | L9: 功能 | M9: 通过 | N9: 通过
A10: TC-006 | B10: 登录注册 | C10: 退出登录 | D10: 退出登录清除状态 | E10: 已登录 | F10: 进入我的页，点击退出登录 | G10: 当前 token 有效 | H10: 清除 token 和当前用户，返回登录页 | I10: 与预期一致 | J10: P0 | K10: 高 | L10: 功能 | M10: 通过 | N10: 通过
A11: TC-007 | B11: 页面导航 | C11: 内容页 | D11: 登录后默认进入内容选择页 | E11: 已登录 | F11: 打开 /app/tree-hole?view=content | G11: 无 | H11: 页面只显示“多 Agent 协助生成”和“直接生成方案”两个入口 | I11: 登录后默认进入多 Agent 协助页， 未进入生成方式选择页 | J11: P0 | K11: 高 | L11: UI/功能 | M11: 失败 | N11: 通过 | O11: BUG-013
A12: TC-008 | B12: 页面导航 | C12: 底部导航 | D12: 底部导航切换页面 | E12: 已登录 | F12: 依次点击 内容、知识库、我的 | G12: 无 | H12: 页面能在三个模块间正常切换，选中状态正确 | I12: 底部导航仍保留旧“圆桌”独立入口 | J12: P1 | K12: 中 | L12: UI/功能 | M12: 失败 | N12: 通过 | O12: BUG-019
A13: TC-009 | B13: 内容生产 | C13: 方式选择 | D13: 选择直接生成方案 | E13: 已登录，进入内容选择页 | F13: 点击“直接生成方案”卡片 | G13: 无 | H13: 进入剧本方案生成表单页 | I13: 内容选择页误显示“先分析内容”和“生成剧本方案”按钮具体需求输入框显示为普通文字 | J13: P0 | K13: 高 | L13: 功能 | M13: 失败 | N13: 通过 | O13: BUG-005、BUG-006
A14: TC-010 | B14: 内容生产 | C14: 方式选择 | D14: 选择多 Agent 协助生成 | E14: 已登录，进入内容选择页 | F14: 点击“多 Agent 协助生成”卡片 | G14: 无 | H14: 进入多 Agent 圆桌页面 | I14: 与预期一致 | J14: P0 | K14: 高 | L14: 功能 | M14: 通过 | N14: 通过
A15: TC-011 | B15: 内容生产 | C15: 表单展示 | D15: 直接生成页表单字段完整 | E15: 进入直接生成方案页 | F15: 查看页面输入项 | G15: 无 | H15: 展示题材类型、平台场景、目标受众、内容风格、具体需求输入框 | I15: 与预期一致 | J15: P0 | K15: 高 | L15: UI/功能 | M15: 通过 | N15: 通过
A16: TC-012 | B16: 内容生产 | C16: 输入框 | D16: 具体需求为可编辑多行文本框 | E16: 进入直接生成方案页 | F16: 查看并编辑具体需求输入框 | G16: 女主被误会后离开... | H16: 输入框显示正常，可编辑多行文本，不再出现标签错乱文字 | I16: 与预期一致 | J16: P0 | K16: 高 | L16: UI/回归 | M16: 通过 | N16: 通过 | O16: 对应历史 Bug 回归
A17: TC-013 | B17: Tool Calling | C17: 内容分析 | D17: 点击先分析内容返回结构化结果 | E17: 直接生成页已填写需求 | F17: 点击“先分析内容” | G17: 追妻火葬场、误会、离开、追悔 | H17: 展示冲突强度、情绪基调、推荐标签、优化建议 | I17: 点击“先分析内容”后结果均为未识别 | J17: P0 | K17: 高 | L17: 功能/AI | M17: 失败 | N17: 通过 | O17: BUG-007
A18: TC-014 | B18: Tool Calling | C18: 字段兼容 | D18: 后端字段不一致时前端兜底分析 | E18: 模拟接口返回字段缺失或不规范 | F18: 点击“先分析内容” | G18: 返回空字段或异常字段 | H18: 前端使用兜底规则，不显示全部“未识别” | I18: 与预期一致 | J18: P1 | K18: 中 | L18: 异常/回归 | M18: 通过 | N18: 通过
A19: TC-015 | B19: 内容生产 | C19: 直接生成 | D19: 直接生成剧本方案 | E19: 完成内容分析或未分析 | F19: 点击“直接生成剧本方案” | G19: 题材=追妻火葬场；平台=短视频漫剧 | H19: 生成包含故事简介、人物设定、核心冲突、分集大纲、关键对白、标题标签和运营建议的方案 | I19: 直接生成与多 Agent 协助生成结果差异不明显 | J19: P0 | K19: 高 | L19: 功能/AI | M19: 失败 | N19: 通过 | O19: BUG-008
A20: TC-016 | B20: 内容生产 | C20: 空输入校验 | D20: 无需求时直接生成拦截 | E20: 直接生成页 | F20: 清空具体需求且无圆桌总结，点击生成 | G20: 空需求 | H20: 系统提示请输入具体需求或先通过圆桌带入总结 | I20: 与预期一致 | J20: P1 | K20: 中 | L20: 异常 | M20: 通过 | N20: 通过
A21: TC-017 | B21: 多 Agent 圆桌 | C21: 页面展示 | D21: 圆桌页展示 Agent 卡片 | E21: 进入多 Agent 协助生成页 | F21: 查看 Agent 列表 | G21: 无 | H21: 展示 16 型人格 Agent 卡片，含名称、图标、角色描述和性别选项 | I21: 与预期一致 | J21: P0 | K21: 高 | L21: UI/功能 | M21: 通过 | N21: 通过
A22: TC-018 | B22: 多 Agent 圆桌 | C22: 默认选择 | D22: 默认选中 4 个 Agent | E22: 进入圆桌页 | F22: 查看右上角已选数量 | G22: 无 | H22: 默认已选 4/4，页面显示选中状态 | I22: 与预期一致 | J22: P2 | K22: 低 | L22: UI | M22: 通过 | N22: 通过
A23: TC-019 | B23: 多 Agent 圆桌 | C23: 数量上限 | D23: 最多选择 4 个 Agent | E23: 圆桌页 | F23: 在已选 4 个基础上继续选择其他 Agent | G23: 第 5 个 Agent | H23: 系统提示最多选择 4 个 Agent，不新增选中 | I23: 选择超过 4 个 Agent 时缺少限制 | J23: P0 | K23: 高 | L23: 边界/异常 | M23: 失败 | N23: 通过 | O23: BUG-009
A24: TC-020 | B24: 多 Agent 圆桌 | C24: 数量下限 | D24: 少于 2 个 Agent 不允许开始圆桌 | E24: 圆桌页 | F24: 取消到只剩 1 个 Agent，点击开始圆桌讨论 | G24: 1 个 Agent | H24: 系统提示至少选择 2 个 Agent | I24: 少于 2 个 Agent 仍可尝试开始圆桌 | J24: P0 | K24: 高 | L24: 边界/异常 | M24: 失败 | N24: 通过 | O24: BUG-010
A25: TC-021 | B25: 多 Agent 圆桌 | C25: 性别设定 | D25: Agent 性别设定可切换 | E25: 圆桌页 | F25: 点击 Agent 卡片的 不限/男/女 | G25: INTJ 设置为男，INFP 设置为女 | H25: 按钮选中状态更新，Prompt 中带入对应性别设定 | I25: 与预期一致 | J25: P1 | K25: 中 | L25: 功能 | M25: 通过 | N25: 通过
A26: TC-022 | B26: 多 Agent 圆桌 | C26: 发起讨论 | D26: 2-4 个 Agent 依次发言 | E26: 已选择 2-4 个 Agent，填写议题 | F26: 点击开始圆桌讨论 | G26: 追妻火葬场漫剧议题 | H26: 每个被选 Agent 至少生成一段发言 | I26: 与预期一致 | J26: P0 | K26: 高 | L26: 功能/AI | M26: 通过 | N26: 通过
A27: TC-023 | B27: 多 Agent 圆桌 | C27: 发言差异 | D27: 不同 Agent 回复视角不同 | E27: 完成圆桌讨论 | F27: 观察 INTJ、INFP、ENTP、ESTJ 发言 | G27: 同一议题 | H27: 发言体现结构、共情、创意、执行等差异，避免简单重复 | I27: 与预期一致 | J27: P1 | K27: 中 | L27: AI专项 | M27: 通过 | N27: 通过
A28: TC-024 | B28: 多 Agent 圆桌 | C28: 圆桌总结 | D28: 生成圆桌总结 | E28: 圆桌讨论完成 | F28: 查看总结区域 | G28: Agent 发言列表 | H28: 生成综合总结，能提炼多 Agent 核心观点 | I28: Agent 卡片模板语法错误导致页面编译失败 | J28: P0 | K28: 高 | L28: 功能/AI | M28: 通过 | N28: 通过 | O28: BUG-012
A29: TC-025 | B29: 圆桌带入 | C29: 带入剧本生成 | D29: 圆桌总结一键带入内容生成 | E29: 已有圆桌总结 | F29: 点击“带入剧本生成” | G29: 圆桌总结文本 | H29: 自动跳转到直接生成页，展示“已带入多 Agent 圆桌总结”区域 | I29: 与预期一致 | J29: P0 | K29: 高 | L29: 功能/回归 | M29: 通过 | N29: 通过
A30: TC-026 | B30: 圆桌带入 | C30: 清空旧分析结果 | D30: 圆桌带入后重新 Tool Calling 分析 | E30: 先执行一次直接分析，再圆桌带入 | F30: 点击生成最终方案 | G30: 原始需求 + 圆桌总结 | H30: 旧 Tool Calling 结果被清空，重新分析新内容 | I30: 圆桌总结带入后仍沿用旧 Tool Calling 结果 | J30: P1 | K30: 中 | L30: 回归/AI | M30: 失败 | N30: 通过 | O30: BUG-011
A31: TC-027 | B31: 圆桌带入 | C31: 最终方案差异 | D31: 圆桌方案区别于直接生成 | E31: 先完成圆桌总结带入 | F31: 点击基于圆桌总结生成最终方案 | G31: 圆桌总结存在 | H31: 结果包含圆桌讨论结论、观点采纳情况、最终剧本方案和影响说明 | I31: 与预期一致 | J31: P0 | K31: 高 | L31: AI专项 | M31: 通过 | N31: 通过
A32: TC-028 | B32: 自定义 Agent | C32: 展开编辑器 | D32: 点击新建人格/角色 | E32: 进入圆桌页 | F32: 点击“+ 新建人格 / 角色” | G32: 无 | H32: 展开自定义 Agent 表单 | I32: 与预期一致 | J32: P1 | K32: 中 | L32: UI/功能 | M32: 通过 | N32: 通过
A33: TC-029 | B33: 自定义 Agent | C33: 创建自定义 Agent | D33: 自定义表单已展开 | E33: 填写角色名称、参考人格、性别、头像、角色设定并保存 | F33: 毒舌女编剧 / ENTP / 女 / 🎭 | G33: 自定义 Agent 保存成功并自动加入圆桌 | H33: 自定义 Agent 保存后未自动加入圆桌 | I33: P0 | J33: 高 | K33: 功能 | L33: 通过 | M33: 失败 | O33: BUG-014
A34: TC-030 | B34: 自定义 Agent | C34: 必填校验 | D34: 缺少角色名称或角色设定 | E34: 展开自定义表单 | F34: 不填角色名称或角色设定，点击保存 | G34: 空名称或空设定 | H34: 系统提示必须填写相关字段 | I34: 与预期一致 | J34: P1 | K34: 中 | L34: 异常 | M34: 通过 | N34: 通过
A35: TC-031 | B35: 自定义 Agent | C35: 删除自定义 Agent | D35: 已有自定义 Agent | E35: 点击自定义 Agent 卡片上的删除 | F35: 自定义 Agent code | G35: Agent 从列表移除，已选列表同步移除 | H35: 删除自定义 Agent 后已选数量未同步变化 | I35: P1 | J35: 中 | K35: 功能/回归 | L35: 通过 | M35: 失败 | O35: BUG-015
A36: TC-032 | B36: RAG 知识库 | C36: 进入知识库页 | D36: 已登录 | E36: 点击底部导航“知识库” | F36: 无 | G36: 进入 Agent 内容知识库页面 | H36: 与预期一致 | I36: P1 | J36: 中 | K36: 页面导航 | L36: 通过 | M36: 通过
A37: TC-033 | B37: RAG 知识库 | C37: 知识库问答 | D37: 进入知识库页 | E37: 输入问题并点击 RAG 生成回答 | F37: 追妻火葬场题材怎么设计强冲突开场？ | G37: 返回知识增强回答，内容与问题相关 | H37: 知识库问答返回结果为空 | I37: P0 | J37: 高 | K37: 功能/AI | L37: 通过 | M37: 失败 | O37: BUG-016
A38: TC-034 | B38: RAG 知识库 | C38: 命中片段展示 | D38: 完成 RAG 问答 | E38: 查看命中知识片段区域 | F38: topK=5 | G38: 展示相关知识片段标题和内容 | H38: 与预期一致 | I38: P1 | J38: 中 | K38: 功能 | L38: 通过 | M38: 通过
A39: TC-035 | B39: RAG 存档 | C39: 存档当前问答 | D39: 已生成 RAG 回答 | E39: 点击存档当前问答 | F39: 当前问题和回答 | G39: 存档列表新增记录，包含问题、回答和时间 | H39: 与预期一致 | I39: P1 | J39: 中 | K39: 功能 | L39: 通过 | M39: 通过
A40: TC-036 | B40: RAG 存档 | C40: 删除存档 | D40: 已有 RAG 存档 | E40: 点击存档卡片删除按钮 | F40: 存档 id | G40: 对应存档从列表移除 | H40: RAG 问答存档删除后页面未及时刷新 | I40: P1 | J40: 中 | K40: 功能 | L40: 通过 | M40: 失败 | O40: BUG-018
A41: TC-037 | B41: 账号隔离 | C41: RAG 存档隔离 | D41: 存在两个账号 | E41: 账号 A 存档，退出后账号 B 登录查看 | F41: A/B 两个账号 | G41: 账号 B 不显示账号 A 的本地存档 | H41: RAG 问答存档未按账号隔离 | I41: P0 | J41: 高 | K41: 安全/回归 | L41: 通过 | M41: 失败 | O41: BUG-017
...

Sheet 统计汇总
A1: 功能测试用例统计汇总
A3: 统计项 | B3: 数量 | D3: 一级模块 | E3: 用例数量 | F3: 通过数
A4: 用例总数 | B4: 45 | D4: RAG 存档 | E4: =COUNTIF(功能测试用例!$B$5:$B$49,D4) -> 2 | F4: =COUNTIFS(功能测试用例!$B$5:$B$49,D4,功能测试用例!$M$5:$M$49,"通过") -> 1
A5: 通过数 | B5: =COUNTIF(功能测试用例!M5:M50,"通过") -> 28 | D5: RAG 知识库 | E5: =COUNTIF(功能测试用例!$B$5:$B$49,D5) -> 3 | F5: =COUNTIFS(功能测试用例!$B$5:$B$49,D5,功能测试用例!$M$5:$M$49,"通过") -> 2
A6: 失败数 | B6: =COUNTIF(功能测试用例!M5:M50,"失败") -> 17 | D6: Tool Calling | E6: =COUNTIF(功能测试用例!$B$5:$B$49,D6) -> 2 | F6: =COUNTIFS(功能测试用例!$B$5:$B$49,D6,功能测试用例!$M$5:$M$49,"通过") -> 1
A7: 待执行数 | B7: =COUNTIF(功能测试用例!M5:M50,"待执行") -> 0 | D7: 兼容性 | E7: =COUNTIF(功能测试用例!$B$5:$B$49,D7) -> 2 | F7: =COUNTIFS(功能测试用例!$B$5:$B$49,D7,功能测试用例!$M$5:$M$49,"通过") -> 2
A8: 阻塞数 | B8: =COUNTIF(功能测试用例!M5:M50,"阻塞") -> 0 | D8: 内容生产 | E8: =COUNTIF(功能测试用例!$B$5:$B$49,D8) -> 6 | F8: =COUNTIFS(功能测试用例!$B$5:$B$49,D8,功能测试用例!$M$5:$M$49,"通过") -> 4
D9: 圆桌带入 | E9: =COUNTIF(功能测试用例!$B$5:$B$49,D9) -> 3 | F9: =COUNTIFS(功能测试用例!$B$5:$B$49,D9,功能测试用例!$M$5:$M$49,"通过") -> 2
A10: 说明：本表用于面试和项目提交展示，执行状态可按实际测试结果更新；下拉选项来源于“数据字典”工作表。 | D10: 多 Agent 圆桌 | E10: =COUNTIF(功能测试用例!$B$5:$B$49,D10) -> 8 | F10: =COUNTIFS(功能测试用例!$B$5:$B$49,D10,功能测试用例!$M$5:$M$49,"通过") -> 6
D11: 我的页面 | E11: =COUNTIF(功能测试用例!$B$5:$B$49,D11) -> 2 | F11: =COUNTIFS(功能测试用例!$B$5:$B$49,D11,功能测试用例!$M$5:$M$49,"通过") -> 2
D12: 接口联调 | E12: =COUNTIF(功能测试用例!$B$5:$B$49,D12) -> 1 | F12: =COUNTIFS(功能测试用例!$B$5:$B$49,D12,功能测试用例!$M$5:$M$49,"通过") -> 1
D13: 测试文档 | E13: =COUNTIF(功能测试用例!$B$5:$B$49,D13) -> 1 | F13: =COUNTIFS(功能测试用例!$B$5:$B$49,D13,功能测试用例!$M$5:$M$49,"通过") -> 1
D14: 登录注册 | E14: =COUNTIF(功能测试用例!$B$5:$B$49,D14) -> 6 | F14: =COUNTIFS(功能测试用例!$B$5:$B$49,D14,功能测试用例!$M$5:$M$49,"通过") -> 4
D15: 自动化测试 | E15: =COUNTIF(功能测试用例!$B$5:$B$49,D15) -> 1 | F15: =COUNTIFS(功能测试用例!$B$5:$B$49,D15,功能测试用例!$M$5:$M$49,"通过") -> 0
D16: 自定义 Agent | E16: =COUNTIF(功能测试用例!$B$5:$B$49,D16) -> 4 | F16: =COUNTIFS(功能测试用例!$B$5:$B$49,D16,功能测试用例!$M$5:$M$49,"通过") -> 2
D17: 账号隔离 | E17: =COUNTIF(功能测试用例!$B$5:$B$49,D17) -> 2 | F17: =COUNTIFS(功能测试用例!$B$5:$B$49,D17,功能测试用例!$M$5:$M$49,"通过") -> 0
D18: 页面导航 | E18: =COUNTIF(功能测试用例!$B$5:$B$49,D18) -> 2 | F18: =COUNTIFS(功能测试用例!$B$5:$B$49,D18,功能测试用例!$M$5:$M$49,"通过") -> 0

Sheet 数据字典
A1: 一级模块 | B1: 优先级 | C1: 严重程度 | D1: 测试类型 | E1: 执行状态
A2: RAG 存档 | B2: P0 | C2: 高 | D2: 功能 | E2: 待执行
A3: RAG 知识库 | B3: P1 | C3: 中 | D3: UI/功能 | E3: 通过
A4: Tool Calling | B4: P2 | C4: 低 | D4: 异常 | E4: 失败
A5: 兼容性 | B5: P3 | D5: 边界/异常 | E5: 阻塞
A6: 内容生产 | D6: 功能/AI
A7: 圆桌带入 | D7: AI专项
A8: 多 Agent 圆桌 | D8: 回归/AI
A9: 我的页面 | D9: 安全/回归
A10: 接口联调 | D10: 接口
A11: 测试文档 | D11: 文档
A12: 登录注册 | D12: 自动化
A13: 自动化测试 | D13: 兼容性
A14: 自定义 Agent | D14: 页面导航
A15: 账号隔离 | D15: UI/文案
A16: 页面导航 | D16: UI/回归
D17: 异常/接口
